Workbook

Sheet Leia-me
B2: MODELO FINANCEIRO REVERSO — CONVENIÊNCIA DELIVERY & RETIRADA
B3: Cuparaque / MG • planejamento a partir da retirada dos sócios, não do produto
B5: COMO USAR
B6: 1. Edite APENAS as células em AMARELO (texto azul). Todo o resto é fórmula e recalcula sozinho.
B7: 2. Todas as premissas ficam na aba 'Premissas' e na aba 'Mix'. Mudou uma, a cascata inteira muda.
B8: 3. A aba 'Cascata' responde: quanto preciso faturar, com que ticket, e quantos pedidos/dia.
B9: 4. A aba 'Demanda' testa se o bairro/cidade COMPORTA esse número de pedidos. É o freio de realidade.
B10: 5. A aba 'Cenários' mostra o que acontece se você mudar ticket médio ou meta de retirada.
B11: 6. A aba 'Ofertas' traduz a meta em produtos, combos e ações concretas.
B13: LEGENDA DE CORES
B14: Amarelo + azul = você edita
B15: Preto = fórmula calculada nesta aba (não mexer)
... B45: 'Demanda' — é a premissa que mais muda o veredito de viabilidade.

Sheet Premissas
B2: PREMISSAS — edite só o amarelo
B4: 1. META DOS SÓCIOS
B5: Item | C5: Valor | E5: Observação / origem do número
B6: Retirada líquida pretendida por sócio (R$/mês) | C6: 3500 | E6: Informado por você. Ambiguidade: assumi R$3.500 POR SÓCIO. Se for R$3.500 no total, mude para 1166,67.
B7: Número de sócios | C7: 3 | E7: Informado por você.
B8: RETIRADA TOTAL DOS SÓCIOS (R$/mês) | C8: =C6*C7 -> 10500 | E8: Este é o 'lucro desejado' do seu exemplo. É o ponto de partida de toda a conta.
B10: 2. CUSTOS FIXOS MENSAIS | E10: TODOS ESTIMADOS POR MIM — não verificados. Substitua por cotação real.
B11: Item | C11: R$/mês | E11: Racional da estimativa
B12: Aluguel de ponto pequeno (30-50m²) | C12: 900 | E12: Ponto simples em cidade do interior de MG. Estimado.
B13: Energia elétrica (freezers/geladeiras/cervejeira) | C13: 700 | E13: Refrigeração 24h é o maior consumo do negócio. Estimado.
B14: Água | C14: 80 | E14: Estimado.
B15: Internet + telefone | C15: 130 | E15: Estimado.
B16: Contador (Simples Nacional) | C16: 400 | E16: Faixa comum de honorário para MEI/ME no interior. Estimado.
B17: Marketing local (impulsionamento + panfleto) | C17: 300 | E17: Verba mínima para tracionar WhatsApp. Estimado.
B18: Manutenção, limpeza e diversos | C18: 200 | E18: Estimado.
B19: Alvará, licenças e taxas (rateio mensal) | C19: 100 | E19: Inclui licença para venda de bebida alcoólica. Estimado.
B20: Salário de funcionário fixo (além dos sócios) | C20: 0 | E20: Zerado: premissa é que os 3 sócios operam. Se contratar, preencha aqui com salário + encargos.
B21: Subtotal | C21: =SUM(C12:C20) -> 2810
B22: Margem de contingência (%) | C22: 0.1 | E22: Colchão para imprevisto. Estimado.
B23: CUSTO FIXO TOTAL (R$/mês) | C23: =C21*(1+C22) -> 3091
B25: 3. CUSTOS VARIÁVEIS | E25: TODOS ESTIMADOS POR MIM — não verificados.
B26: Item | C26: Valor | E26: Racional da estimativa
B27: CMV médio ponderado (% da receita) | C27: =Mix!$D$20 -> 0.6735 | E27: NÃO editar aqui. Vem da aba 'Mix' — muda automaticamente quando você altera o mix de produtos.
B28: Taxa de cartão/Pix (% da receita) | C28: 0.018 | E28: Média ponderada débito/crédito/Pix. Estimado — negocie com a adquirente.
B29: Perdas, quebras e validade vencida (% da receita) | C29: 0.015 | E29: Vidro quebrado, produto vencido, furto. Estimado.
B30: Custo pago por entrega (R$/pedido) | C30: 3.5 | E30: Valor pago ao entregador por corrida. Estimado — cidade pequena, distâncias curtas.
B31: Taxa de entrega cobrada do cliente (R$/pedido) | C31: 3 | E31: Repassada ao cliente. Se der entrega grátis, coloque 0.
B32: % dos pedidos que são delivery (resto é retirada) | C32: 0.75 | E32: Estimado. Retirada não gera custo de entrega — quanto mais retirada, melhor a margem.
B33: Embalagem por pedido (R$) | C33: 1.2 | E33: Sacola, gelo de transporte, fita. Estimado.
B35: 4. IMPOSTO — SIMPLES NACIONAL ANEXO I (COMÉRCIO) | E35: FAIXAS A CONFERIR COM CONTADOR. Ver aviso na aba 'Leia-me'.
B36: Faturamento bruto dos últimos 12 meses (RBT12) estimado | C36: 877000 | E36: Evita cálculo circular. Depois de rodar a cascata, volte aqui e iguale ao 'Faturamento anualizado' da aba 'Cascata'.
B37: Tabela de faixas (não editar sem orientação do contador)
B38: Limite inferior (R$) | C38: Alíquota nominal | D38: Parcela a deduzir (R$)
B39: 0 | C39: 0.04 | D39: 0
B40: 180000.01 | C40: 0.073 | D40: 5940
B41: 360000.01 | C41: 0.095 | D41: 13860
B42: 720000.01 | C42: 0.107 | D42: 22500
B43: 1800000 | C43: 0.143 | D43: 87300
B44: 3600000 | C44: 0.19 | D44: 378000
B45: Alíquota nominal aplicável | C45: =INDEX($C$39:$C$44,MATCH(Premissas!$C$36,$B$39:$B$44,1)) -> 0.107
...

Sheet Mix
B2: MIX DE PRODUTOS — o que define a sua margem
B3: A soma da coluna 'Participação' precisa dar 100%. O CMV ponderado alimenta a aba Premissas automaticamente.
B5: Categoria | C5: Participação na receita | D5: CMV (%) | E5: Margem bruta (%) | F5: Contribuição para o CMV | G5: Papel estratégico da categoria
B6: Cerveja gelada (lata / long neck) | C6: 0.4 | D6: 0.72 | E6: =1-D6 -> 0.28 | F6: =C6*D6 -> 0.288 | G6: Motor de volume. Margem baixa, giro altíssimo. É o que traz o pedido.
B7: Refrigerante, água e energético | C7: 0.15 | D7: 0.65 | E7: =1-D7 -> 0.35 | F7: =C7*D7 -> 0.0975 | G7: Complemento natural da cerveja. Bom para combo.
B8: Destilados, vinho e ice | C8: 0.1 | D8: 0.58 | E8: =1-D8 -> 0.42 | F8: =C8*D8 -> 0.058 | G8: Ticket alto por unidade. Puxa o ticket médio para cima.
B9: Snacks, salgadinho, chocolate, amendoim | C9: 0.12 | D9: 0.62 | E9: =1-D9 -> 0.38 | F9: =C9*D9 -> 0.0744 | G9: Item de impulso. Margem melhor. Alvo n.º 1 de upsell.
B10: Gelo, carvão, descartáveis, isqueiro | C10: 0.08 | D10: 0.4 | E10: =1-D10 -> 0.6 | F10: =C10*D10 -> 0.032 | G10: MAIOR MARGEM da loja. Quase ninguém compra separado — sempre oferecer junto.
B11: Cigarro e tabacaria | C11: 0.08 | D11: 0.88 | E11: =1-D11 -> 0.12 | F11: =C11*D11 -> 0.0704 | G11: Margem quase nula. Serve só como isca de tráfego. Não promover.
B12: Mercearia emergencial (arroz, óleo, pão, ovo) | C12: 0.07 | D12: 0.76 | E12: =1-D12 -> 0.24 | F12: =C12*D12 -> 0.0532 | G12: Captura a compra de urgência fora do horário do mercado.
B13: TOTAL | C13: =SUM(C6:C12) -> 1 | F13: =SUM(F6:F12) -> 0.6735 | G13: Se o TOTAL da participação não der 100%, o modelo inteiro fica errado.
B15: Checagem de consistência
B16: =IF(ROUND(C13,4)=1,"OK — participações somam 100%","ERRO — as participações somam "&TEXT(C13,"0.0%")&". Corrija antes de usar o modelo.") -> OK — participações somam 100%
B19: CMV MÉDIO PONDERADO
B20: CMV ponderado (usado em toda a planilha) | D20: =F13 -> 0.6735 | G20: Este é o número que a aba Premissas puxa. NÃO editar diretamente — edite o mix acima.
B22: TODOS os percentuais de CMV acima são estimativas minhas de faixas típicas de varejo de conveniência.
B23: NÃO são cotação real de distribuidor. Peça tabela de preço a 2 distribuidores da região e substitua.

Sheet Cascata
B2: CASCATA — da retirada dos sócios até pedidos por dia
B3: Nada aqui é editável. Tudo vem de 'Premissas' e 'Mix'.
B5: Passo | C5: Valor | E5: O que significa
B6: 1. Retirada pretendida pelos sócios (R$/mês) | C6: =Premissas!$C$8 -> 10500 | E6: Ponto de partida. O que os 3 sócios querem tirar juntos.
B7: 2. Custos fixos totais (R$/mês) | C7: =Premissas!$C$23 -> 3091 | E7: Sai independente de vender ou não.
B8: 3. Resultado que a operação precisa gerar (R$/mês) | C8: =C6+C7 -> 13591 | E8: Soma de 1 + 2. É o que a margem de contribuição tem que cobrir.
B10: 4. Ticket médio planejado (R$) | C10: =Premissas!$C$54 -> 55 | E10: Vem de Premissas. É a alavanca principal.
B11: 5. (−) CMV por pedido | C11: =-C10*Premissas!$C$27 -> -37.0425 | E11: Custo da mercadoria vendida, ponderado pelo mix.
B12: 6. (−) Imposto (Simples efetivo) por pedido | C12: =-C10*Premissas!$C$47 -> -4.4739396 | E12: Provavelmente superestimado — ver nota sobre Substituição Tributária.
B13: 7. (−) Taxa de cartão/Pix por pedido | C13: =-C10*Premissas!$C$28 -> -0.99
B14: 8. (−) Perdas e quebras por pedido | C14: =-C10*Premissas!$C$29 -> -0.825
B15: 9. (−) Custo líquido de entrega por pedido | C15: =-(Premissas!$C$30-Premissas!$C$31)*Premissas!$C$32 -> -0.375 | E15: Custo pago menos taxa cobrada, aplicado só sobre a fatia que é delivery. Se a taxa cobrir o custo, isto vira zero ou positivo.
B16: 10. (−) Embalagem por pedido | C16: =-Premissas!$C$33 -> -1.2
B17: MARGEM DE CONTRIBUIÇÃO POR PEDIDO (R$) | C17: =SUM(C10:C16) -> 10.09356 | E17: Quanto SOBRA de cada pedido para pagar fixo + retirada. Se for negativo ou perto de zero, o modelo não fecha de jeito nenhum.
B18: Margem de contribuição (% do ticket) | C18: =IFERROR(Cascata!$C$17/C10,0) -> 0.18351928 | E18: No exemplo da pizzaria, este era o '50%' que estava implícito e não declarado.
B20: RESULTADO
B21: Indicador | C21: Valor | E21: Leitura
B22: PEDIDOS NECESSÁRIOS POR MÊS | C22: =IFERROR(Cascata!$C$8/Cascata!$C$17,0) -> 1346.5021 | E22: Resultado que precisa cobrir fixo + retirada, dividido pela margem de cada pedido.
B23: FATURAMENTO NECESSÁRIO POR MÊS (R$) | C23: =Cascata!$C$22*C10 -> 74057.614 | E23: Pedidos × ticket médio.
B24: Faturamento anualizado (R$) — use na célula RBT12 | C24: =Cascata!$C$23*12 -> 888691.37 | E24: Copie este valor para a célula RBT12 na aba Premissas e recalcule. Uma ou duas rodadas convergem.
B25: PEDIDOS POR DIA | C25: =IFERROR(Cascata!$C$22/Premissas!$C$51,0) -> 44.883402 | E25: Este é o número que você testa contra a realidade do bairro na aba 'Demanda'.
B26: Pedidos por hora de operação | C26: =IFERROR(Cascata!$C$25/Premissas!$C$52,0) -> 4.9870447 | E26: Teste operacional: 3 sócios dão conta desse ritmo, considerando pico concentrado à noite?
B27: Faturamento por dia (R$) | C27: =IFERROR(Cascata!$C$23/Premissas!$C$51,0) -> 2468.5871
B29: PONTO DE EQUILÍBRIO (sem retirada dos sócios)
B30: Pedidos/mês só para pagar os custos fixos | C30: =IFERROR(Premissas!$C$23/Cascata!$C$17,0) -> 306.23485 | E30: Abaixo disso, o negócio dá prejuízo e os sócios não tiram nada.
B31: Pedidos/dia só para pagar os custos fixos | C31: =IFERROR(C30/Premissas!$C$51,0) -> 10.207828 | E31: Este é o seu piso de sobrevivência.
B32: Faturamento/mês no ponto de equilíbrio (R$) | C32: =C30*C10 -> 16842.917

Sheet Demanda
B2: TESTE DE REALIDADE — o mercado comporta essa meta?
B3: É aqui que a maioria dos planos de conveniência quebra. A conta financeira fecha; o tamanho da cidade não.
B5: 1. TAMANHO DO MERCADO
B6: Item | C6: Valor | E6: Origem
B7: População do município (hab.) | C7: 3958 | E7: Fornecido por você: projeção 2026 para Cuparaque/MG. Não verificado por mim de forma independente.
B8: Moradores por domicílio | C8: 3.1 | E8: ESTIMADO por mim. Não é dado do IBGE que eu tenha conferido. Ajuste se souber o real.
B9: Domicílios totais no município | C9: =IFERROR(C7/C8,0) -> 1276.7742
B10: % dos domicílios no alcance da entrega | C10: 0.8 | E10: ESTIMADO. Densidade de 17,6 hab/km² com população concentrada no núcleo urbano e no distrito de Aldeia — Aldeia pode ficar fora do raio viável.
B11: DOMICÍLIOS ENDEREÇÁVEIS | C11: =C9*C10 -> 1021.4194
B13: 2. QUANTO O MODELO EXIGE DO MERCADO
B14: Item | C14: Valor | E14: Leitura
B15: Pedidos/mês exigidos pela meta | C15: =Cascata!$C$22 -> 1346.5021 | E15: Vem da aba Cascata.
B16: Pedidos por domicílio endereçável por mês | C16: =IFERROR(C15/Demanda!$C$11,0) -> 1.3182657 | E16: TESTE-CHAVE: é o número de vezes que CADA casa do bairro teria que comprar, por mês, para a meta fechar.
B17: Faturamento exigido por domicílio por mês (R$) | C17: =IFERROR(Cascata!$C$23/Demanda!$C$11,0) -> 72.504612 | E17: Quanto cada casa teria que gastar SÓ NA SUA LOJA, todo mês.
B19: 3. COMPARAÇÃO COM A RENDA LOCAL
B20: Item | C20: Valor | E20: Origem / leitura
B21: PIB per capita anual (R$) | C21: 20995.06 | E21: Fornecido por você.
B22: PIB per capita mensal (R$) | C22: =C21/12 -> 1749.5883 | E22: ATENÇÃO: PIB per capita NÃO é renda disponível da família. Inclui administração pública (40,7% do PIB local) e agropecuária. A renda real que entra na casa é bem menor.
B23: PIB mensal por domicílio (R$) — proxy grosseiro de renda | C23: =C22*C8 -> 5423.7238 | E23: Proxy otimista. Use como TETO, nunca como renda efetiva.
B24: % da 'renda' do domicílio que iria para a sua loja | C24: =IFERROR(C17/C23,0) -> 0.01336805 | E24: Regra de bolso: conveniência/bebida raramente passa de 3-5% do orçamento familiar em cidade de baixa renda. Acima disso, a meta é irreal. ESTA REGRA DE BOLSO É ESTIMATIVA MINHA, não é dado de pesquisa.
B26: 4. VEREDITO AUTOMÁTICO
B27: =IF(C24>0.05,"INVIÁVEL COMO ESTÁ — a meta exige mais de 5% do orçamento de cada domicílio. Reduza a retirada, aumente o ticket ou amplie o raio de entrega.",IF(C24>0.03,"ESTICADO — exige entre 3% e 5% do orçamento de cada domicílio. Possível, mas depende de execução muito boa e de captar público de fora da cidade.","PLAUSÍVEL — exige menos de 3% do orçamento de cada domicílio. Dentro do que uma conveniência costuma capturar.")) -> PLAUSÍVEL — exige menos de 3% do orçamento de cada domicílio. Dentro do que uma conveniência costuma capturar.
B29: =IF(Demanda!$C$16>4,"ALERTA DE FREQUÊNCIA: o modelo exige mais de 4 compras por domicílio por mês. Isso pressupõe um hábito de recompra muito alto para uma cidade deste porte.","Frequência exigida por domicílio dentro de faixa defensável.") -> Frequência exigida por domicílio dentro de faixa defensável.
B32: 5. FATORES QUE AMPLIAM O MERCADO ALÉM DO CÁLCULO ACIMA
B33: • AgroCupira (feira agropecuária regional): pico de consumo no 1º semestre, com público de fora. Trate como receita EXTRA de 1-2 meses, nunca como base do plano mensal.
B34: • Fluxo esportivo regional sazonal: gera demanda de bebida e gelo em fins de semana específicos.
B35: • Administração pública = 40,7% do PIB: renda estável e com data certa. O pico de vendas tende a se concentrar nos dias seguintes ao pagamento do funcionalismo. Planeje estoque e promoção em torno desse calendário.
B36: • Distrito de Aldeia: se entrar no raio de entrega, amplia a base de domicílios. Exige avaliar custo/tempo de deslocamento — ajuste a célula C10 e o custo por entrega.
B37: • Obras públicas em 2026 (pavimentação, reforma do CEMEI): injetam renda temporária de mão de obra local. Efeito de curto prazo, não estrutural.
B39: Saldo de emprego formal em 2026: 37 admissões contra 42 desligamentos (saldo −5). Mercado de trabalho estagnado — não conte com crescimento orgânico de consumidores. A população também caiu 14,89% no último Censo.

Sheet Cenarios
B2: SENSIBILIDADE — o efeito de mudar o ticket médio
B3: Cada linha recalcula a cascata inteira para um ticket diferente, mantendo todas as outras premissas.
B5: Ticket médio (R$) | C5: Margem contrib. p/ pedido (R$) | D5: Pedidos/mês | E5: Pedidos/dia | F5: Faturamento/mês (R$) | G5: Compras por domicílio/mês | H5: % do orçamento do domicílio
B6: 35 | C6: =B6*(1-Premissas!$C$27-Premissas!$C$47-Premissas!$C$28-Premissas!$C$29)-(Premissas!$C$30-Premissas!$C$31)*Premissas!$C$32-Premissas!$C$33 -> 5.8504475 | D6: =IFERROR(Cascata!$C$8/C6,0) -> 2323.0701 | E6: =IFERROR(D6/Premissas!$C$51,0) -> 77.435671 | F6: =D6*B6 -> 81307.455 | G6: =IFERROR(D6/Demanda!$C$11,0) -> 2.2743549 | H6: =IFERROR(F6/Demanda!$C$11/Demanda!$C$23,0) -> 0.01467671
B7: 45 | C7: =B7*(1-Premissas!$C$27-Premissas!$C$47-Premissas!$C$28-Premissas!$C$29)-(Premissas!$C$30-Premissas!$C$31)*Premissas!$C$32-Premissas!$C$33 -> 7.972004 | D7: =IFERROR(Cascata!$C$8/C7,0) -> 1704.8411 | E7: =IFERROR(D7/Premissas!$C$51,0) -> 56.828036 | F7: =D7*B7 -> 76717.849 | G7: =IFERROR(D7/Demanda!$C$11,0) -> 1.6690903 | H7: =IFERROR(F7/Demanda!$C$11/Demanda!$C$23,0) -> 0.013848246
B8: 55 | C8: =B8*(1-Premissas!$C$27-Premissas!$C$47-Premissas!$C$28-Premissas!$C$29)-(Premissas!$C$30-Premissas!$C$31)*Premissas!$C$32-Premissas!$C$33 -> 10.09356 | D8: =IFERROR(Cascata!$C$8/C8,0) -> 1346.5021 | E8: =IFERROR(D8/Premissas!$C$51,0) -> 44.883402 | F8: =D8*B8 -> 74057.614 | G8: =IFERROR(D8/Demanda!$C$11,0) -> 1.3182657 | H8: =IFERROR(F8/Demanda!$C$11/Demanda!$C$23,0) -> 0.01336805
B9: 65 | C9: =B9*(1-Premissas!$C$27-Premissas!$C$47-Premissas!$C$28-Premissas!$C$29)-(Premissas!$C$30-Premissas!$C$31)*Premissas!$C$32-Premissas!$C$33 -> 12.215117 | D9: =IFERROR(Cascata!$C$8/C9,0) -> 1112.6377 | E9: =IFERROR(D9/Premissas!$C$51,0) -> 37.087925 | F9: =D9*B9 -> 72321.453 | G9: =IFERROR(D9/Demanda!$C$11,0) -> 1.0893055 | H9: =IFERROR(F9/Demanda!$C$11/Demanda!$C$23,0) -> 0.013054658
B10: 75 | C10: =B10*(1-Premissas!$C$27-Premissas!$C$47-Premissas!$C$28-Premissas!$C$29)-(Premissas!$C$30-Premissas!$C$31)*Premissas!$C$32-Premissas!$C$33 -> 14.336673 | D10: =IFERROR(Cascata!$C$8/C10,0) -> 947.9884 | E10: =IFERROR(D10/Premissas!$C$51,0) -> 31.599613 | F10: =D10*B10 -> 71099.13 | G10: =IFERROR(D10/Demanda!$C$11,0) -> 0.92810891 | H10: =IFERROR(F10/Demanda!$C$11/Demanda!$C$23,0) -> 0.012834018
B11: 90 | C11: =B11*(1-Premissas!$C$27-Premissas!$C$47-Premissas!$C$28-Premissas!$C$29)-(Premissas!$C$30-Premissas!$C$31)*Premissas!$C$32-Premissas!$C$33 -> 17.519008 | D11: =IFERROR(Cascata!$C$8/C11,0) -> 775.78594 | E11: =IFERROR(D11/Premissas!$C$51,0) -> 25.859531 | F11: =D11*B11 -> 69820.734 | G11: =IFERROR(D11/Demanda!$C$11,0) -> 0.75951756 | H11: =IFERROR(F11/Demanda!$C$11/Demanda!$C$23,0) -> 0.012603256
B12: 110 | C12: =B12*(1-Premissas!$C$27-Premissas!$C$47-Premissas!$C$28-Premissas!$C$29)-(Premissas!$C$30-Premissas!$C$31)*Premissas!$C$32-Premissas!$C$33 -> 21.762121 | D12: =IFERROR(Cascata!$C$8/C12,0) -> 624.52553 | E12: =IFERROR(D12/Premissas!$C$51,0) -> 20.817518 | F12: =D12*B12 -> 68697.808 | G12: =IFERROR(D12/Demanda!$C$11,0) -> 0.61142911 | H12: =IFERROR(F12/Demanda!$C$11/Demanda!$C$23,0) -> 0.012400558
B14: Como ler
B15: • Ticket maior = menos pedidos para a mesma meta = menos pressão sobre uma cidade pequena. Por isso o ticket é a alavanca mais importante aqui.
B16: • Mas ticket alto demais afasta a compra por impulso, que é a essência de conveniência. O equilíbrio está em subir o ticket por COMBO, não por preço unitário alto.
B17: • A coluna '% do orçamento do domicílio' é o freio: quanto mais alta, mais irreal a meta para o tamanho de Cuparaque.
B19: SENSIBILIDADE — meta de retirada por sócio
B20: Retirada por sócio (R$) | C20: Retirada total (R$) | D20: Resultado necessário (R$) | E20: Pedidos/mês | F20: Pedidos/dia | G20: Faturamento/mês (R$) | H20: % do orçamento do domicílio
B21: 1500 | C21: =B21*Premissas!$C$7 -> 4500 | D21: =C21+Premissas!$C$23 -> 7591 | E21: =IFERROR(D21/Cascata!$C$17,0) -> 752.06366 | F21: =IFERROR(E21/Premissas!$C$51,0) -> 25.068789 | G21: =E21*Premissas!$C$54 -> 41363.501 | H21: =IFERROR(G21/Demanda!$C$11/Demanda!$C$23,0) -> 0.0074664755
B22: 2000 | C22: =B22*Premissas!$C$7 -> 6000 | D22: =C22+Premissas!$C$23 -> 9091 | E22: =IFERROR(D22/Cascata!$C$17,0) -> 900.67326 | F22: =IFERROR(E22/Premissas!$C$51,0) -> 30.022442 | G22: =E22*Premissas!$C$54 -> 49537.029 | H22: =IFERROR(G22/Demanda!$C$11/Demanda!$C$23,0) -> 0.0089418691
B23: 2500 | C23: =B23*Premissas!$C$7 -> 7500 | D23: =C23+Premissas!$C$23 -> 10591 | E23: =IFERROR(D23/Cascata!$C$17,0) -> 1049.2829 | F23: =IFERROR(E23/Premissas!$C$51,0) -> 34.976095 | G23: =E23*Premissas!$C$54 -> 57710.558 | H23: =IFERROR(G23/Demanda!$C$11/Demanda!$C$23,0) -> 0.010417263
B24: 3000 | C24: =B24*Premissas!$C$7 -> 9000 | D24: =C24+Premissas!$C$23 -> 12091 | E24: =IFERROR(D24/Cascata!$C$17,0) -> 1197.8925 | F24: =IFERROR(E24/Premissas!$C$51,0) -> 39.929749 | G24: =E24*Premissas!$C$54 -> 65884.086 | H24: =IFERROR(G24/Demanda!$C$11/Demanda!$C$23,0) -> 0.011892656
B25: 3500 | C25: =B25*Premissas!$C$7 -> 10500 | D25: =C25+Premissas!$C$23 -> 13591 | E25: =IFERROR(D25/Cascata!$C$17,0) -> 1346.5021 | F25: =IFERROR(E25/Premissas!$C$51,0) -> 44.883402 | G25: =E25*Premissas!$C$54 -> 74057.614 | H25: =IFERROR(G25/Demanda!$C$11/Demanda!$C$23,0) -> 0.01336805
B26: 4500 | C26: =B26*Premissas!$C$7 -> 13500 | D26: =C26+Premissas!$C$23 -> 16591 | E26: =IFERROR(D26/Cascata!$C$17,0) -> 1643.7213 | F26: =IFERROR(E26/Premissas!$C$51,0) -> 54.790709 | G26: =E26*Premissas!$C$54 -> 90404.67 | H26: =IFERROR(G26/Demanda!$C$11/Demanda!$C$23,0) -> 0.016318837
B27: 6000 | C27: =B27*Premissas!$C$7 -> 18000 | D27: =C27+Premissas!$C$23 -> 21091 | E27: =IFERROR(D27/Cascata!$C$17,0) -> 2089.5501 | F27: =IFERROR(E27/Premissas!$C$51,0) -> 69.651669 | G27: =E27*Premissas!$C$54 -> 114925.25 | H27: =IFERROR(G27/Demanda!$C$11/Demanda!$C$23,0) -> 0.020745018

Sheet Ofertas
B2: OFERTAS E PRODUTOS — como construir o ticket planejado
B3: Combos desenhados para PUXAR O TICKET, não para dar desconto. Preços e custos abaixo são estimativas minhas.
B5: Combo / oferta | C5: Preço de venda (R$) | D5: Custo estimado (R$) | E5: Margem (R$) | F5: Margem (%) | G5: vs. ticket planejado | H5: Função no modelo econômico
B6: Combo Fim de Semana 12 latas + 2 pacotes de gelo + amendoim | C6: 89.9 | D6: 62 | E6: =C6-D6 -> 27.9 | F6: =IFERROR(E6/C6,0) -> 0.31034483 | G6: =IFERROR(IF(C6>Premissas!$C$54,"+"&TEXT(C6/Premissas!$C$54-1,"0%")&" acima",TEXT(C6/Premissas!$C$54-1,"0%")&" abaixo"),"-") -> +63% acima | H6: Ancora o ticket bem acima da média. Gelo e amendoim carregam a margem que a cerveja não dá.
B7: Combo Churrasco carvão + gelo + descartáveis + 6 latas | C7: 74.9 | D7: 47 | E7: =C7-D7 -> 27.9 | F7: =IFERROR(E7/C7,0) -> 0.37249666 | G7: =IFERROR(IF(C7>Premissas!$C$54,"+"&TEXT(C7/Premissas!$C$54-1,"0%")&" acima",TEXT(C7/Premissas!$C$54-1,"0%")&" abaixo"),"-") -> +36% acima | H7: Categoria de MAIOR margem da loja (gelo/carvão/descartável) empacotada com o produto de maior giro.
B8: Combo Dupla 6 latas + 1 salgadinho grande | C8: 44.9 | D8: 31 | E8: =C8-D8 -> 13.9 | F8: =IFERROR(E8/C8,0) -> 0.30957684 | G8: =IFERROR(IF(C8>Premissas!$C$54,"+"&TEXT(C8/Premissas!$C$54-1,"0%")&" acima",TEXT(C8/Premissas!$C$54-1,"0%")&" abaixo"),"-") -> -18% abaixo | H8: Entrada acessível. Serve para converter quem pediria só 'duas cervejas'.
B9: Kit Drink em Casa 1 destilado + 2 energéticos + gelo | C9: 119.9 | D9: 76 | E9: =C9-D9 -> 43.9 | F9: =IFERROR(E9/C9,0) -> 0.36613845 | G9: =IFERROR(IF(C9>Premissas!$C$54,"+"&TEXT(C9/Premissas!$C$54-1,"0%")&" acima",TEXT(C9/Premissas!$C$54-1,"0%")&" abaixo"),"-") -> +118% acima | H9: Maior ticket do cardápio. Público jovem, noite de sexta/sábado.
B10: Emergência da Madrugada mercearia básica + bebida | C10: 59.9 | D10: 44 | E10: =C10-D10 -> 15.9 | F10: =IFERROR(E10/C10,0) -> 0.2654424 | G10: =IFERROR(IF(C10>Premissas!$C$54,"+"&TEXT(C10/Premissas!$C$54-1,"0%")&" acima",TEXT(C10/Premissas!$C$54-1,"0%")&" abaixo"),"-") -> +9% acima | H10: Captura a compra fora do horário do mercado. Margem baixa, mas fideliza e cria hábito de recompra.
B11: Assinatura Semanal entrega fixa combinada toda sexta | C11: 79.9 | D11: 54 | E11: =C11-D11 -> 25.9 | F11: =IFERROR(E11/C11,0) -> 0.32415519 | G11: =IFERROR(IF(C11>Premissas!$C$54,"+"&TEXT(C11/Premissas!$C$54-1,"0%")&" acima",TEXT(C11/Premissas!$C$54-1,"0%")&" abaixo"),"-") -> +45% acima | H11: Receita previsível. É o único item que ataca o problema real: a FREQUÊNCIA de recompra numa cidade pequena.
B12: Ticket planejado (referência) | C12: =Premissas!$C$54 -> 55
B14: PRINCÍPIOS DE PRECIFICAÇÃO PARA ESTE MODELO
B15: • Cerveja é ISCA, não é lucro. CMV de ~72% significa que vender só cerveja não paga a operação. Ela existe para gerar o pedido; a margem vem do que vai junto.
B16: • Gelo, carvão e descartáveis são o motor de margem (CMV ~40%). Nunca devem ser vendidos isolados — sempre empacotados. Ninguém compara preço de gelo.
B17: • Cigarro tem CMV ~88%. Vale ter para não perder o cliente, mas jamais promover ou destacar. É custo de tráfego.
B18: • O desconto do combo deve ser MENOR que o ganho de margem do item agregado. Combo que só dá desconto destrói o modelo em vez de sustentá-lo.
B19: • Ticket mínimo para delivery protege a margem: pedido de R$15 com R$3,50 de entrega + R$1,20 de embalagem tem margem de contribuição próxima de zero.
B20: • Retirada tem margem maior que delivery. Vale criar incentivo explícito para retirar (ex.: item brinde acima de X), porque melhora a margem sem baixar preço.
B22: ALAVANCAS PARA ATINGIR A META, EM ORDEM DE IMPACTO
B23: 1. FREQUÊNCIA — em cidade de 4 mil habitantes o limite não é quantas pessoas existem, é quantas vezes cada uma compra. Assinatura semanal e programa de recompra valem mais que qualquer campanha de aquisição.
B24: 2. TICKET via combo — subir de R$55 para R$75 derruba os pedidos/dia necessários em ~27%, sem precisar de mais clientes.
B25: 3. MIX — deslocar participação de cigarro e cerveja para gelo/carvão/snacks melhora o CMV ponderado e reduz o faturamento necessário.
B26: 4. RAIO — incluir o distrito de Aldeia amplia a base de domicílios. Simule mudando a célula C10 da aba 'Demanda'.
... B30: Preços e custos dos combos acima são ESTIMATIVAS MINHAS para dar forma ao raciocínio. Não são cotação real.
